Workbook

Sheet Petunjuk
A1: LEMBAR KODING PERTAHANAN MCP (v1.1) - untuk Section 6 / Tabel 16
A2: Korpus: 186 record MCP-spesifik setelah dedup putaran kedua (file final_corpus_ids_186.csv).
A4: CARA MENGISI
A5: 1. Kolom KUNING = diisi manusia. Kolom ABU-ABU = informasi. Kolom BIRU = rumus otomatis (jangan diedit).
A6: 2. Urutan kerja: baris "kandidat_agent" dulu, lalu "kandidat_cek_recall" (agent melabeli none, tetapi judul/abstrak menunjukkan pertahanan), lalu "scan_cepat" (cukup pastikan peran bukan pertahanan).
A7: 3. Isi kolom "peran" untuk semua baris. Kolom mekanisme dan evaluasi hanya untuk peran defense_primary, defense_secondary, dan proposal_only.
A8: 4. Kode evaluasi dari bagian metode/eksperimen teks lengkap, bukan dari judul atau abstrak. Tanpa teks lengkap: isi peran, nama, paradigma, mekanisme; kosongkan kolom evaluasi (teks_lengkap_tersedia = tidak).
A9: 5. Kolom "kutipan_adaptif" wajib bila adaptif = ya (maks 25 kata, persis dari paper). Kolom "lokasi_bukti" wajib untuk setiap entri yang dievaluasi.
A10: 6. Maturitas dihitung otomatis: L3 = spec_normatif atau produksi_bukti_publik; L2 = ada evaluasi independen; L1 = dievaluasi penulis sendiri; L0 = tanpa evaluasi (isi jenis_evaluasi = none). Jangan diisi manual.
A11: 7. Kolom "cek_konsistensi" harus kosong pada baris yang sudah selesai. Bila berisi PERIKSA, perbaiki isian.
A12: 8. Sheet "Ringkasan" menghitung semua statistik langsung dari Koding (dengan penyebut). Jangan salin angka dari ingatan.
A13: 9. Satu paper dengan beberapa pertahanan terpisah: duplikasi barisnya (salin baris, ubah nama_pertahanan), jangan menggabungkan.
A15: CONTOH PENGISIAN (bukan data nyata; kolom sama dengan sheet Koding)
B16: peran | C16: paradigma | D16: llm_dlm_keputusan | E16: titik_penegakan | F16: crossings | G16: kelas_diklaim | H16: kelas_dievaluasi | I16: jenis_evaluasi | J16: asal_set_serangan | K16: adaptif | L16: kutipan_adaptif | M16: lokasi_bukti | N16: deployment | O16: maturitas (hasil rumus)
B17: defense_primary | C17: isolation_containment | D17: tidak | E17: S | F17: R5 | G17: C5 | H17: C5 | I17: author_run | J17: authors_own | K17: tidak | L17: (kosong) | M17: Section 5, Table 3 | N17: prototype_open_source | O17: L1
B18: Contoh: sandbox subprocess yang dievaluasi penulis pada 20 kasus path traversal dengan set serangan buatan sendiri; tidak ada serangan yang disesuaikan terhadap sandbox, jadi adaptif = tidak.

Sheet Koding
A1: record_id | B1: judul | C1: tahun | D1: tier | E1: triase | F1: agent_role (referensi) | G1: tautan | H1: teks_lengkap_tersedia | I1: peran | J1: nama_pertahanan | K1: paradigma | L1: ringkasan_mekanisme (kata sendiri, maks 2 kalimat) | M1: llm_dlm_keputusan | N1: titik_penegakan | O1: crossings (R1-R7, pisah ;) | P1: kelas_diklaim (A1-D3, pisah ;) | Q1: kelas_dievaluasi (hanya yang ada eksperimen) | R1: jenis_evaluasi | S1: evaluator_independen (record_id) | T1: asal_set_serangan | U1: adaptif | V1: kutipan_adaptif (maks 25 kata) | W1: lokasi_bukti (bagian/tabel/hal.) | X1: deployment | Y1: biaya_utilitas | Z1: catatan | AA1: maturitas (otomatis) | AB1: cek_konsistensi (otomatis) | AC1: korpus_v5 | AD1: kode_eksklusi_v5 | AE1: catatan_audit_v5
A2: aditi-2025-model-context-protocol-vision-systems | B2: Model Context Protocol for Vision Systems: Audit, Security, and Protocol Extensions | C2: 2025 | D2: E2 | E2: kandidat_agent | F2: primary | G2: https://arxiv.org/abs/2509.22814 | H2: ya | I2: proposal_only | J2: unnamed:vision-protocol-extensions | K2: protocol_provision | L2: Usulan ekstensi skema semantik MCP dan validator prototipe untuk membatasi aksi visi di testbed terkontrol. | M2: tidak | N2: registry | O2: R2;R5 | P2: A3;B3;C5 | R2: none | T2: none | U2: n/a_tanpa_evaluasi | X2: none | Y2: not_reported | Z2: Proposal ekstensi protokol MCP dengan skema semantik dan validator prototipe tanpa evaluasi terhadap serangan. Catatan deployment: prototipe internal/eksperimental (belum dirilis secara publik). | AA2: =IF(I2="","",IF(OR(I2="attack",I2="survey_review",I2="benchmark_measurement",I2="position_other",I2="not_defense"),"n/a",IF(OR(X2="spec_normatif",X2="produksi_bukti_publik"),"L3",IF(ISNUMBER(SEARCH("independent",R2)),"L2",IF(R2="author_run","L1",IF(R2="none","L0","")))))) | AB2: =IF(I2="","",IF(AND(K2="deterministic_policy",M2="ya"),"PERIKSA: deterministic_policy tetapi LLM/ML ada dalam keputusan. ","")&IF(AND(U2="ya",V2=""),"PERIKSA: adaptif=ya wajib ada kutipan. ","")&IF(AND(R2="none",U2<>"n/a_tanpa_evaluasi",U2<>""),"PERIKSA: tanpa evaluasi, adaptif harus n/a. ","")&IF(AND(OR(R2="author_run",R2="author_run+independent",R2="independent_only"),Q2=""),"PERIKSA: isi kelas_dievaluasi. ","")&IF(AND(OR(R2="author_run",R2="author_run+independent",R2="independent_only"),W2=""),"PERIKSA: isi lokasi_bukti. ","")&IF(AND(H2="tidak",R2<>""),"PERIKSA: tanpa teks lengkap, kosongkan kolom evaluasi. ","")) | AC2: include
A3: alexander-2026-task-conditioned-least-privilege-learning | B3: Task-Conditioned Least-Privilege Learning for Executable Terminal and MCP Agents | C3: 2026 | D3: E2 | E3: kandidat_agent | F3: primary | G3: https://arxiv.org/abs/2608.18351 | H3: tidak | I3: not_defense | Z3: [AUDIT_v5_EXCLUDE: EC2] Dikeluarkan dari korpus MCP-spesifik oleh audit reviewer kedua v5. Pembelajaran least-privilege terminal/agen umum dengan MCP hanya alat pengganti insidental. | AA3: =IF(I3="","",IF(OR(I3="attack",I3="survey_review",I3="benchmark_measurement",I3="position_other",I3="not_defense"),"n/a",IF(OR(X3="spec_normatif",X3="produksi_bukti_publik"),"L3",IF(ISNUMBER(SEARCH("independent",R3)),"L2",IF(R3="author_run","L1",IF(R3="none","L0","")))))) | AB3: =IF(I3="","",IF(AND(K3="deterministic_policy",M3="ya"),"PERIKSA: deterministic_policy tetapi LLM/ML ada dalam keputusan. ","")&IF(AND(U3="ya",V3=""),"PERIKSA: adaptif=ya wajib ada kutipan. ","")&IF(AND(R3="none",U3<>"n/a_tanpa_evaluasi",U3<>""),"PERIKSA: tanpa evaluasi, adaptif harus n/a. ","")&IF(AND(OR(R3="author_run",R3="author_run+independent",R3="independent_only"),Q3=""),"PERIKSA: isi kelas_dievaluasi. ","")&IF(AND(OR(R3="author_run",R3="author_run+independent",R3="independent_only"),W3=""),"PERIKSA: isi lokasi_bukti. ","")&IF(AND(H3="tidak",R3<>""),"PERIKSA: tanpa teks lengkap, kosongkan kolom evaluasi. ","")) | AC3: exclude | AD3: EC2 | AE3: audit lanjutan; diterima koordinator
A4: alfonso-2026-mcp-seclint-open-source-static | B4: MCP-SecLint: An Open-Source Static Analyzer for Detecting Vulnerabilities in LLM Tool Integrations | C4: 2026 | D4: E1 | E4: kandidat_agent | F4: primary | G4: https://doi.org/10.1145/3806007.3810961 | H4: ya | I4: defense_primary | J4: MCP-SecLint | K4: content_inspection_static | L4: Penganalisis statis offline kode server MCP untuk mendeteksi eksekusi perintah berbahaya, token passthrough, dan endpoint tanpa autentikasi. | M4: tidak | N4: offline_analysis | O4: R4;R5 | P4: C5;C3 | Q4: C5;C3 | R4: author_run | T4: third_party_public | U4: tidak | W4: Abstract / hal. 1 | X4: none | Y4: not_reported | Z4: Penganalisis statis MCP-SecLint untuk mendeteksi dangerous sinks (C5) dan unauthenticated endpoints (C3) pada implementasi server MCP. Klaim C1 dicabut karena analisis statis kode server tidak menangani confused deputy planner. Catatan deployment: prototipe internal/eksperimental (belum dirilis secara publik). | AA4: =IF(I4="","",IF(OR(I4="attack",I4="survey_review",I4="benchmark_measurement",I4="position_other",I4="not_defense"),"n/a",IF(OR(X4="spec_normatif",X4="produksi_bukti_publik"),"L3",IF(ISNUMBER(SEARCH("independent",R4)),"L2",IF(R4="author_run","L1",IF(R4="none","L0","")))))) | AB4: =IF(I4="","",IF(AND(K4="deterministic_policy",M4="ya"),"PERIKSA: deterministic_policy tetapi LLM/ML ada dalam keputusan. ","")&IF(AND(U4="ya",V4=""),"PERIKSA: adaptif=ya wajib ada kutipan. ","")&IF(AND(R4="none",U4<>"n/a_tanpa_evaluasi",U4<>""),"PERIKSA: tanpa evaluasi, adaptif harus n/a. ","")&IF(AND(OR(R4="author_run",R4="author_run+independent",R4="independent_only"),Q4=""),"PERIKSA: isi kelas_dievaluasi. ","")&IF(AND(OR(R4="author_run",R4="author_run+independent",R4="independent_only"),W4=""),"PERIKSA: isi lokasi_bukti. ","")&IF(AND(H4="tidak",R4<>""),"PERIKSA: tanpa teks lengkap, kosongkan kolom evaluasi. ","")) | AC4: include
A5: alfredo-2026-attested-tool-server-admission-security | B5: Attested Tool-Server Admission: A Security Extension to the Model Context Protocol | C5: 2026 | D5: E2 | E5: kandidat_agent | F5: primary | G5: https://arxiv.org/abs/2605.24248 | H5: ya | I5: defense_primary | J5: mcp-attested | K5: integrity_provenance | L5: Mekanisme admisi server teratestasi kriptografis Ed25519 dengan validasi clearance assertion terhadap root trust pinned dan allowlist deny-by-default. | M5: tidak | N5: registry | O5: R7 | P5: B1;B2 | Q5: B1;B2 | R5: author_run | T5: authors_own | U5: tidak | W5: Sec 7.1; Sec 7.2; Tabel hal. 12 | X5: none | Y5: not_reported | Z5: Mekanisme admisi server teratestasi Ed25519 mcp-attested dengan allowlist deny-by-default, diuji pada 48 kasus tes hermetik & adversarial. Catatan deployment: prototipe internal/eksperimental (belum dirilis secara publik). | AA5: =IF(I5="","",IF(OR(I5="attack",I5="survey_review",I5="benchmark_measurement",I5="position_other",I5="not_defense"),"n/a",IF(OR(X5="spec_normatif",X5="produksi_bukti_publik"),"L3",IF(ISNUMBER(SEARCH("independent",R5)),"L2",IF(R5="author_run","L1",IF(R5="none","L0","")))))) | AB5: =IF(I5="","",IF(AND(K5="deterministic_policy",M5="ya"),"PERIKSA: deterministic_policy tetapi LLM/ML ada dalam keputusan. ","")&IF(AND(U5="ya",V5=""),"PERIKSA: adaptif=ya wajib ada kutipan. ","")&IF(AND(R5="none",U5<>"n/a_tanpa_evaluasi",U5<>""),"PERIKSA: tanpa evaluasi, adaptif harus n/a. ","")&IF(AND(OR(R5="author_run",R5="author_run+independent",R5="independent_only"),Q5=""),"PERIKSA: isi kelas_dievaluasi. ","")&IF(AND(OR(R5="author_run",R5="author_run+independent",R5="independent_only"),W5=""),"PERIKSA: isi lokasi_bukti. ","")&IF(AND(H5="tidak",R5<>""),"PERIKSA: tanpa teks lengkap, kosongkan kolom evaluasi. ","")) | AC5: include
A6: alfredo-2026-enclawed-configurable-sector-neutral-hardening | B6: enclawed: A Configurable, Sector-Neutral Hardening Framework for Single-User AI Assistant Gateways | C6: 2026 | D6: E2 | E6: kandidat_agent | F6: primary | G6: https://arxiv.org/abs/2604.16838 | H6: tidak | I6: not_defense | Z6: [AUDIT_v5_EXCLUDE: EC2] Dikeluarkan dari korpus MCP-spesifik oleh audit reviewer kedua v5. Hardening gateway asisten OpenClaw berbasis Bell-LaPadula; MCP insidental. | AA6: =IF(I6="","",IF(OR(I6="attack",I6="survey_review",I6="benchmark_measurement",I6="position_other",I6="not_defense"),"n/a",IF(OR(X6="spec_normatif",X6="produksi_bukti_publik"),"L3",IF(ISNUMBER(SEARCH("independent",R6)),"L2",IF(R6="author_run","L1",IF(R6="none","L0","")))))) | AB6: =IF(I6="","",IF(AND(K6="deterministic_policy",M6="ya"),"PERIKSA: deterministic_policy tetapi LLM/ML ada dalam keputusan. ","")&IF(AND(U6="ya",V6=""),"PERIKSA: adaptif=ya wajib ada kutipan. ","")&IF(AND(R6="none",U6<>"n/a_tanpa_evaluasi",U6<>""),"PERIKSA: tanpa evaluasi, adaptif harus n/a. ","")&IF(AND(OR(R6="author_run",R6="author_run+independent",R6="independent_only"),Q6=""),"PERIKSA: isi kelas_dievaluasi. ","")&IF(AND(OR(R6="author_run",R6="author_run+independent",R6="independent_only"),W6=""),"PERIKSA: isi lokasi_bukti. ","")&IF(AND(H6="tidak",R6<>""),"PERIKSA: tanpa teks lengkap, kosongkan kolom evaluasi. ","")) | AC6: exclude | AD6: EC2 | AE6: audit lanjutan; diterima koordinator
A7: anthropic-2024-model-context-protocol-specification-architecture | B7: Model Context Protocol Specification (Architecture & Security) | C7: 2024 | D7: E3 | E7: kandidat_agent | F7: primary | H7: ya | I7: position_other | Z7: Spesifikasi arsitektural protokol MCP resmi Anthropic (revisi 2024-11-05). Ketentuan normatif dilaporkan di Section 5 (Tabel 14-15), bukan sebagai L3 pertahanan literatur. | AA7: =IF(I7="","",IF(OR(I7="attack",I7="survey_review",I7="benchmark_measurement",I7="position_other",I7="not_defense"),"n/a",IF(OR(X7="spec_normatif",X7="produksi_bukti_publik"),"L3",IF(ISNUMBER(SEARCH("independent",R7)),"L2",IF(R7="author_run","L1",IF(R7="none","L0","")))))) | AB7: =IF(I7="","",IF(AND(K7="deterministic_policy",M7="ya"),"PERIKSA: deterministic_policy tetapi LLM/ML ada dalam keputusan. ","")&IF(AND(U7="ya",V7=""),"PERIKSA: adaptif=ya wajib ada kutipan. ","")&IF(AND(R7="none",U7<>"n/a_tanpa_evaluasi",U7<>""),"PERIKSA: tanpa evaluasi, adaptif harus n/a. ","")&IF(AND(OR(R7="author_run",R7="author_run+independent",R7="independent_only"),Q7=""),"PERIKSA: isi kelas_dievaluasi. ","")&IF(AND(OR(R7="author_run",R7="author_run+independent",R7="independent_only"),W7=""),"PERIKSA: isi lokasi_bukti. ","")&IF(AND(H7="tidak",R7<>""),"PERIKSA: tanpa teks lengkap, kosongkan kolom evaluasi. ","")) | AC7: include
A8: baichao-2026-flowguard-signals-evidence-mcp-security | B8: FlowGuard: From Signals to Evidence for MCP Security Detection | C8: 2026 | D8: E2 | E8: kandidat_agent | F8: primary | G8: https://arxiv.org/abs/2607.14754 | H8: ya | I8: defense_primary | J8: FlowGuard | K8: content_inspection_runtime | L8: Sistem pemindai keamanan MCP aktif berbasis probing bertahap (recon & strike) yang memverifikasi bukti runtime pada pemanggilan tool dan menganalisis risiko semantik metadata menggunakan LLM bounded. | M8: ya | N8: H | O8: R2;R4;R5 | P8: A1;A2;C3;C5 | Q8: A1;A2;C3;C5 | R8: author_run | T8: authors_own | U8: tidak | W8: Sec V; Table II; Table IV; hal. 7-10 | X8: none | Y8: latensi dilaporkan (reduksi 2.23x, Tabel IV) | Z8: Pemindai keamanan MCP dua fase (reconnaissance & targeted strike) dengan adjudikasi bukti berbasis Qwen3-235B. Diuji pada 1.880 kasus benchmark buatan penulis dan 8.000 server MCPZoo; ancaman adaptif eksplisit di luar cakupan. Catatan deployment: prototipe internal/eksperimental (belum dirilis secara publik). | AA8: =IF(I8="","",IF(OR(I8="attack",I8="survey_review",I8="benchmark_measurement",I8="position_other",I8="not_defense"),"n/a",IF(OR(X8="spec_normatif",X8="produksi_bukti_publik"),"L3",IF(ISNUMBER(SEARCH("independent",R8)),"L2",IF(R8="author_run","L1",IF(R8="none","L0","")))))) | AB8: =IF(I8="","",IF(AND(K8="deterministic_policy",M8="ya"),"PERIKSA: deterministic_policy tetapi LLM/ML ada dalam keputusan. ","")&IF(AND(U8="ya",V8=""),"PERIKSA: adaptif=ya wajib ada kutipan. ","")&IF(AND(R8="none",U8<>"n/a_tanpa_evaluasi",U8<>""),"PERIKSA: tanpa evaluasi, adaptif harus n/a. ","")&IF(AND(OR(R8="author_run",R8="author_run+independent",R8="independent_only"),Q8=""),"PERIKSA: isi kelas_dievaluasi. ","")&IF(AND(OR(R8="author_run",R8="author_run+independent",R8="independent_only"),W8=""),"PERIKSA: isi lokasi_bukti. ","")&IF(AND(H8="tidak",R8<>""),"PERIKSA: tanpa teks lengkap, kosongkan kolom evaluasi. ","")) | AC8: include
A9: bin-2025-mcpguard-automatically-detecting-vulnerabilities-mcp | B9: MCPGuard : Automatically Detecting Vulnerabilities in MCP Servers | C9: 2025 | D9: E2 | E9: kandidat_agent | F9: primary | G9: https://arxiv.org/abs/2510.23673 | H9: ya | I9: survey_review | Z9: Makalah survei/lanskap keamanan MCP dan tinjauan taksonomis komprehensif atas pertahanan yang ada (server-side scanning & runtime monitoring) tanpa evaluasi atau implementasi mekanisme baru oleh penulis. KODER 1 keliru menganggap judul 'MCPGuard' sebagai defense_primary. | AA9: =IF(I9="","",IF(OR(I9="attack",I9="survey_review",I9="benchmark_measurement",I9="position_other",I9="not_defense"),"n/a",IF(OR(X9="spec_normatif",X9="produksi_bukti_publik"),"L3",IF(ISNUMBER(SEARCH("independent",R9)),"L2",IF(R9="author_run","L1",IF(R9="none","L0","")))))) | AB9: =IF(I9="","",IF(AND(K9="deterministic_policy",M9="ya"),"PERIKSA: deterministic_policy tetapi LLM/ML ada dalam keputusan. ","")&IF(AND(U9="ya",V9=""),"PERIKSA: adaptif=ya wajib ada kutipan. ","")&IF(AND(R9="none",U9<>"n/a_tanpa_evaluasi",U9<>""),"PERIKSA: tanpa evaluasi, adaptif harus n/a. ","")&IF(AND(OR(R9="author_run",R9="author_run+independent",R9="independent_only"),Q9=""),"PERIKSA: isi kelas_dievaluasi. ","")&IF(AND(OR(R9="author_run",R9="author_run+independent",R9="independent_only"),W9=""),"PERIKSA: isi lokasi_bukti. ","")&IF(AND(H9="tidak",R9<>""),"PERIKSA: tanpa teks lengkap, kosongkan kolom evaluasi. ","")) | AC9: include
A10: chenkai-2026-when-agentic-executions-fail-detecting | B10: When Agentic Executions Fail: Detecting and Localizing Runtime Faults from Telemetry | C10: 2026 | D10: E2 | E10: kandidat_agent | F10: primary | G10: https://arxiv.org/abs/2608.14680 | H10: ya | I10: benchmark_measurement | Z10: Makalah kontribusi utamanya adalah benchmark injeksi kesalahan runtime (AgentChaosBench) berisi 275 jejak telemetri Langfuse pada 5 aplikasi multi-agen (MCP & A2A) dengan evaluasi baseline LLM diagnostik (zero-shot LLM baselines); tidak mengusulkan mekanisme pertahanan baru. KODER 1 keliru menetapkannya sebagai defense_primary. | AA10: =IF(I10="","",IF(OR(I10="attack",I10="survey_review",I10="benchmark_measurement",I10="position_other",I10="not_defense"),"n/a",IF(OR(X10="spec_normatif",X10="produksi_bukti_publik"),"L3",IF(ISNUMBER(SEARCH("independent",R10)),"L2",IF(R10="author_run","L1",IF(R10="none","L0","")))))) | AB10: =IF(I10="","",IF(AND(K10="deterministic_policy",M10="ya"),"PERIKSA: deterministic_policy tetapi LLM/ML ada dalam keputusan. ","")&IF(AND(U10="ya",V10=""),"PERIKSA: adaptif=ya wajib ada kutipan. ","")&IF(AND(R10="none",U10<>"n/a_tanpa_evaluasi",U10<>""),"PERIKSA: tanpa evaluasi, adaptif harus n/a. ","")&IF(AND(OR(R10="author_run",R10="author_run+independent",R10="independent_only"),Q10=""),"PERIKSA: isi kelas_dievaluasi. ","")&IF(AND(OR(R10="author_run",R10="author_run+independent",R10="independent_only"),W10=""),"PERIKSA: isi lokasi_bukti. ","")&IF(AND(H10="tidak",R10<>""),"PERIKSA: tanpa teks lengkap, kosongkan kolom evaluasi. ","")) | AC10: include
A11: chenning-2026-adr-agentic-detection-system-enterprise | B11: ADR: An Agentic Detection System for Enterprise Agentic AI Security | C11: 2026 | D11: E2 | E11: kandidat_agent | F11: primary | G11: https://arxiv.org/abs/2605.17380 | H11: ya | I11: defense_primary | J11: ADR | K11: content_inspection_runtime | L11: Sistem deteksi ancaman agen enterprise dua tingkat (triage cepat berbasis heuristik/klasifikator dan penalaran mendalam berbasis LLM) yang menginspeksi telemetri runtime, jejak penalaran, dan pemanggilan tool MCP. | M11: ya | N11: H | O11: R2;R3;R5;R6;R7 | P11: A1;A2;A3;B1;B2;C1;C2;C5;D1;D2;D3;OUT_OF_TAXONOMY:resource_abuse | Q11: A1;A2;C1;C5;D1;D2;D3;OUT_OF_TAXONOMY:resource_abuse | R11: author_run | T11: mixed | U11: tidak | W11: Sec. 4-5, Tabel 2, Gbr 6a, hal. 8-10 | X11: none | Y11: biaya ($0.024/task) & latensi (18.5s) dilaporkan (Sec 5.2, Fig 6b) | Z11: ADR dievaluasi pada ADR-Bench (17 teknik, 5 taktik) & AgentDojo mencakup 8 kelas (termasuk C5 Code Interpreter & Operational Impact: Resource Exhaustion/DoS dipetakan ke OUT_OF_TAXONOMY:resource_abuse). Kode repositori publik modelcon. Catatan deployment: prototipe internal/eksperimental (belum dirilis secara publik). | AA11: =IF(I11="","",IF(OR(I11="attack",I11="survey_review",I11="benchmark_measurement",I11="position_other",I11="not_defense"),"n/a",IF(OR(X11="spec_normatif",X11="produksi_bukti_publik"),"L3",IF(ISNUMBER(SEARCH("independent",R11)),"L2",IF(R11="author_run","L1",IF(R11="none","L0","")))))) | AB11: =IF(I11="","",IF(AND(K11="deterministic_policy",M11="ya"),"PERIKSA: deterministic_policy tetapi LLM/ML ada dalam keputusan. ","")&IF(AND(U11="ya",V11=""),"PERIKSA: adaptif=ya wajib ada kutipan. ","")&IF(AND(R11="none",U11<>"n/a_tanpa_evaluasi",U11<>""),"PERIKSA: tanpa evaluasi, adaptif harus n/a. ","")&IF(AND(OR(R11="author_run",R11="author_run+independent",R11="independent_only"),Q11=""),"PERIKSA: isi kelas_dievaluasi. ","")&IF(AND(OR(R11="author_run",R11="author_run+independent",R11="independent_only"),W11=""),"PERIKSA: isi lokasi_bukti. ","")&IF(AND(H11="tidak",R11<>""),"PERIKSA: tanpa teks lengkap, kosongkan kolom evaluasi. ","")) | AC11: include
A12: christoph-2025-agentbound-securing-execution-boundaries-ai | B12: AgentBound: Securing Execution Boundaries of AI Agents | C12: 2025 | D12: E1 | E12: kandidat_agent | F12: primary | G12: https://arxiv.org/abs/2510.21236 | H12: ya | I12: defense_primary | J12: AgentBound | K12: isolation_containment | L12: Kerangka pengamanan eksekusi server MCP berbasis deklarasi kapabilitas (AgentManifest) dan sandbox kontainer (AgentBox) yang mengisolasi akses berkas, jaringan, dan lingkungan secara deterministik. | M12: tidak | N12: H | O12: R5;R6 | P12: B1;C5;D1 | Q12: C5;D1 | R12: author_run | T12: mixed | U12: tidak | W12: Sec 4; Sec 4.2; Sec 4.3; Table 2; hal. 11-16 | X12: none | Y12: latensi dan overhead kontainer dilaporkan (Sec 4.3) | Z12: Eksekusi server di dalam kontainer AgentBox (Docker) menegakkan batas isolasi proses dan pembatasan kapabilitas manifest; mengevaluasi rug pull (B1), scope server (C5), dan eksfiltrasi data (D1). C1 dicabut karena isolasi proses bukan mediasi otorisasi sesi planner. Catatan deployment: prototipe internal/eksperimental (belum dirilis secara publik). | AA12: =IF(I12="","",IF(OR(I12="attack",I12="survey_review",I12="benchmark_measurement",I12="position_other",I12="not_defense"),"n/a",IF(OR(X12="spec_normatif",X12="produksi_bukti_publik"),"L3",IF(ISNUMBER(SEARCH("independent",R12)),"L2",IF(R12="author_run","L1",IF(R12="none","L0","")))))) | AB12: =IF(I12="","",IF(AND(K12="deterministic_policy",M12="ya"),"PERIKSA: deterministic_policy tetapi LLM/ML ada dalam keputusan. ","")&IF(AND(U12="ya",V12=""),"PERIKSA: adaptif=ya wajib ada kutipan. ","")&IF(AND(R12="none",U12<>"n/a_tanpa_evaluasi",U12<>""),"PERIKSA: tanpa evaluasi, adaptif harus n/a. ","")&IF(AND(OR(R12="author_run",R12="author_run+independent",R12="independent_only"),Q12=""),"PERIKSA: isi kelas_dievaluasi. ","")&IF(AND(OR(R12="author_run",R12="author_run+independent",R12="independent_only"),W12=""),"PERIKSA: isi lokasi_bukti. ","")&IF(AND(H12="tidak",R12<>""),"PERIKSA: tanpa teks lengkap, kosongkan kolom evaluasi. ","")) | AC12: include
A13: dongxu-2026-device-context-protocol-compact-safety | B13: Device Context Protocol: A Compact, Safety-First Architecture for LLM-Driven Control of Constrained Devices | C13: 2026 | D13: E2 | E13: kandidat_agent | F13: primary | G13: https://arxiv.org/abs/2605.26159 | H13: ya | I13: defense_primary | J13: Device Context Protocol | K13: protocol_provision | L13: Protokol biner kompak (DCP) dengan host-side Bridge yang memvalidasi skema kapabilitas wajib per-intent, batasan rentang, serta dry-run sebelum instruksi LLM mencapai perangkat fisik. | M13: tidak | N13: gateway_proxy | O13: R2;R5 | P13: A2;C5 | Q13: A2;C5 | R13: author_run | T13: mixed | U13: tidak | W13: Sec 4; Sec 5; Fig 3; hal. 8-10 | X13: none | Y13: footprint firmware (27.6 KB flash, 0.6 KB RAM) & latensi dilaporkan | Z13: Protokol keamanan berorientasi perangkat terbatas (DCP) dengan host Bridge penegak kapabilitas deterministik. Diuji pada 675 panggilan dari 5 LLM komersial terhadap 6 kategori serangan termasuk injeksi AgentDojo. Catatan deployment: prototipe internal/eksperimental (belum dirilis secara publik). | AA13: =IF(I13="","",IF(OR(I13="attack",I13="survey_review",I13="benchmark_measurement",I13="position_other",I13="not_defense"),"n/a",IF(OR(X13="spec_normatif",X13="produksi_bukti_publik"),"L3",IF(ISNUMBER(SEARCH("independent",R13)),"L2",IF(R13="author_run","L1",IF(R13="none","L0","")))))) | AB13: =IF(I13="","",IF(AND(K13="deterministic_policy",M13="ya"),"PERIKSA: deterministic_policy tetapi LLM/ML ada dalam keputusan. ","")&IF(AND(U13="ya",V13=""),"PERIKSA: adaptif=ya wajib ada kutipan. ","")&IF(AND(R13="none",U13<>"n/a_tanpa_evaluasi",U13<>""),"PERIKSA: tanpa evaluasi, adaptif harus n/a. ","")&IF(AND(OR(R13="author_run",R13="author_run+independent",R13="independent_only"),Q13=""),"PERIKSA: isi kelas_dievaluasi. ","")&IF(AND(OR(R13="author_run",R13="author_run+independent",R13="independent_only"),W13=""),"PERIKSA: isi lokasi_bukti. ","")&IF(AND(H13="tidak",R13<>""),"PERIKSA: tanpa teks lengkap, kosongkan kolom evaluasi. ","")) | AC13: include
A14: fatemeh-2026-federated-mcp-gateway-enforceable-isolation | B14: A Federated MCP Gateway: Enforceable Isolation and Measuring Residual Semantic Attacks | C14: 2026 | D14: E1 | E14: kandidat_agent | F14: primary | G14: https://doi.org/10.1109/noms69089.2026.11668221 | H14: ya | I14: defense_primary | J14: Federated MCP Gateway | K14: isolation_containment | L14: Gateway federasi MCP terpusat dengan kontrol isolasi tenant berbasis JWT, verifikasi skema, dan filter regex/firewall output terhadap serangan semantik residu. | M14: tidak | N14: gateway_proxy | O14: R1;R2;R3;R5 | P14: A2;D1;D2;OUT_OF_TAXONOMY:resource_abuse | Q14: A2;D1;D2;OUT_OF_TAXONOMY:resource_abuse | R14: author_run | T14: authors_own | U14: tidak | W14: Sec. IV, Tabel III, hal. 4-6 | X14: none | Y14: dilaporkan: tingkat blokir dan mismatch per modul penegakan (Tabel III) | Z14: Federated MCP Gateway (defense_primary, L1). Isolasi tenant/identitas (D1;D2), pemfilteran regex (A2), dan kontrol amplifikasi sumber daya 100 req/menit (OUT_OF_TAXONOMY:resource_abuse). Suite 93 kasus sintetik; adaptif=tidak. | AA14: =IF(I14="","",IF(OR(I14="attack",I14="survey_review",I14="benchmark_measurement",I14="position_other",I14="not_defense"),"n/a",IF(OR(X14="spec_normatif",X14="produksi_bukti_publik"),"L3",IF(ISNUMBER(SEARCH("independent",R14)),"L2",IF(R14="author_run","L1",IF(R14="none","L0","")))))) | AB14: =IF(I14="","",IF(AND(K14="deterministic_policy",M14="ya"),"PERIKSA: deterministic_policy tetapi LLM/ML ada dalam keputusan. ","")&IF(AND(U14="ya",V14=""),"PERIKSA: adaptif=ya wajib ada kutipan. ","")&IF(AND(R14="none",U14<>"n/a_tanpa_evaluasi",U14<>""),"PERIKSA: tanpa evaluasi, adaptif harus n/a. ","")&IF(AND(OR(R14="author_run",R14="author_run+independent",R14="independent_only"),Q14=""),"PERIKSA: isi kelas_dievaluasi. ","")&IF(AND(OR(R14="author_run",R14="author_run+independent",R14="independent_only"),W14=""),"PERIKSA: isi lokasi_bukti. ","")&IF(AND(H14="tidak",R14<>""),"PERIKSA: tanpa teks lengkap, kosongkan kolom evaluasi. ","")) | AC14: include
A15: gamini-2026-mcp-secure-runtime-access-control | B15: MCP-Secure: A Runtime Access Control Layer for Privilege-Aware LLM Agent Tooling | C15: 2026 | D15: E1 | E15: kandidat_agent | F15: primary | G15: https://doi.org/10.1109/ojcs.2026.3664314 | H15: ya | I15: defense_primary | J15: MCP-Secure | K15: deterministic_policy | L15: Lapisan kontrol akses runtime host-side berbasis state machine level-sesi dengan izin default read-only dan approval gating untuk eskalasi hak istimewa pemanggilan tool. | M15: tidak | N15: H | O15: R3;R5 | P15: C1;C5 | Q15: C1;C5 | R15: author_run | T15: authors_own | U15: tidak | W15: Sec. IV-V; hal. 508-512 | X15: none | Y15: dilaporkan: overhead runtime minimal mempertahankan utilitas (Sec. V) | Z15: Teks lengkap IEEE OJCS (Vol. 7, pp. 504-513). Evaluasi author_run pada 1.080 eksekusi simulasi adversarial: mengurangi blast radius tool berbahaya/halusinasi dan mengendalikan eskalasi wewenang. Catatan deployment: prototipe internal/eksperimental (belum dirilis secara publik). | AA15: =IF(I15="","",IF(OR(I15="attack",I15="survey_review",I15="benchmark_measurement",I15="position_other",I15="not_defense"),"n/a",IF(OR(X15="spec_normatif",X15="produksi_bukti_publik"),"L3",IF(ISNUMBER(SEARCH("independent",R15)),"L2",IF(R15="author_run","L1",IF(R15="none","L0","")))))) | AB15: =IF(I15="","",IF(AND(K15="deterministic_policy",M15="ya"),"PERIKSA: deterministic_policy tetapi LLM/ML ada dalam keputusan. ","")&IF(AND(U15="ya",V15=""),"PERIKSA: adaptif=ya wajib ada kutipan. ","")&IF(AND(R15="none",U15<>"n/a_tanpa_evaluasi",U15<>""),"PERIKSA: tanpa evaluasi, adaptif harus n/a. ","")&IF(AND(OR(R15="author_run",R15="author_run+independent",R15="independent_only"),Q15=""),"PERIKSA: isi kelas_dievaluasi. ","")&IF(AND(OR(R15="author_run",R15="author_run+independent",R15="independent_only"),W15=""),"PERIKSA: isi lokasi_bukti. ","")&IF(AND(H15="tidak",R15<>""),"PERIKSA: tanpa teks lengkap, kosongkan kolom evaluasi. ","")) | AC15: include
A16: genliang-2026-runtime-authorization-resources-acquired-ai | B16: Runtime Authorization for Resources Acquired by AI Agents | C16: 2026 | D16: E2 | E16: kandidat_agent | F16: primary | G16: https://arxiv.org/abs/2609.14744 | H16: tidak | I16: not_defense | Z16: [AUDIT_v5_EXCLUDE: EC2] Dikeluarkan dari korpus MCP-spesifik oleh audit reviewer kedua v5. Makalah otorisasi sumber daya runtime agen umum di mana MCP hanya format perolehan sumber daya insidental. | AA16: =IF(I16="","",IF(OR(I16="attack",I16="survey_review",I16="benchmark_measurement",I16="position_other",I16="not_defense"),"n/a",IF(OR(X16="spec_normatif",X16="produksi_bukti_publik"),"L3",IF(ISNUMBER(SEARCH("independent",R16)),"L2",IF(R16="author_run","L1",IF(R16="none","L0","")))))) | AB16: =IF(I16="","",IF(AND(K16="deterministic_policy",M16="ya"),"PERIKSA: deterministic_policy tetapi LLM/ML ada dalam keputusan. ","")&IF(AND(U16="ya",V16=""),"PERIKSA: adaptif=ya wajib ada kutipan. ","")&IF(AND(R16="none",U16<>"n/a_tanpa_evaluasi",U16<>""),"PERIKSA: tanpa evaluasi, adaptif harus n/a. ","")&IF(AND(OR(R16="author_run",R16="author_run+independent",R16="independent_only"),Q16=""),"PERIKSA: isi kelas_dievaluasi. ","")&IF(AND(OR(R16="author_run",R16="author_run+independent",R16="independent_only"),W16=""),"PERIKSA: isi lokasi_bukti. ","")&IF(AND(H16="tidak",R16<>""),"PERIKSA: tanpa teks lengkap, kosongkan kolom evaluasi. ","")) | AC16: exclude | AD16: EC2 | AE16: dikeluarkan setelah audit reviewer kedua + rekonsiliasi
A17: giovanni-2026-mandato-protocol-level-enforcement-digitally | B17: Mandato: Protocol-Level Enforcement of Digitally Signed Mandates on AI Agent Actions with Cryptographically Chained Audit Trails | C17: 2026 | D17: E2 | E17: kandidat_agent | F17: primary | G17: https://arxiv.org/abs/2608.14074 | H17: ya | I17: proposal_only | J17: MANDATO | K17: capability_or_token | L17: Proxy tata kelola MCP yang memvalidasi mandat bertanda tangan digital pada aksi agen dan mencatat jejak audit terantai kriptografis secara tamper-evident. | M17: tidak | N17: gateway_proxy | O17: R3;R5 | P17: C1;C2;C3 | R17: none | T17: none | U17: n/a_tanpa_evaluasi | X17: none | Y17: not_reported | Z17: Proxy tata kelola MCP untuk mandat bertanda tangan digital. Penulis menyatakan status epistemik sistem masih dalam pengembangan (system under construction) tanpa hasil empiris. KODER 1 menandai defense_primary dengan jenis_evaluasi: none (L0). | AA17: =IF(I17="","",IF(OR(I17="attack",I17="survey_review",I17="benchmark_measurement",I17="position_other",I17="not_defense"),"n/a",IF(OR(X17="spec_normatif",X17="produksi_bukti_publik"),"L3",IF(ISNUMBER(SEARCH("independent",R17)),"L2",IF(R17="author_run","L1",IF(R17="none","L0","")))))) | AB17: =IF(I17="","",IF(AND(K17="deterministic_policy",M17="ya"),"PERIKSA: deterministic_policy tetapi LLM/ML ada dalam keputusan. ","")&IF(AND(U17="ya",V17=""),"PERIKSA: adaptif=ya wajib ada kutipan. ","")&IF(AND(R17="none",U17<>"n/a_tanpa_evaluasi",U17<>""),"PERIKSA: tanpa evaluasi, adaptif harus n/a. ","")&IF(AND(OR(R17="author_run",R17="author_run+independent",R17="independent_only"),Q17=""),"PERIKSA: isi kelas_dievaluasi. ","")&IF(AND(OR(R17="author_run",R17="author_run+independent",R17="independent_only"),W17=""),"PERIKSA: isi lokasi_bukti. ","")&IF(AND(H17="tidak",R17<>""),"PERIKSA: tanpa teks lengkap, kosongkan kolom evaluasi. ","")) | AC17: include
A18: guanlin-2025-zero-knowledge-audit-internet-agents | B18: Zero-Knowledge Audit for Internet of Agents: Privacy-Preserving Communication Verification with Model Context Protocol | C18: 2025 | D18: E2 | E18: kandidat_agent | F18: primary | G18: https://arxiv.org/abs/2512.14737 | H18: ya | I18: defense_primary | J18: zk-MCP | K18: integrity_provenance | L18: Protokol audit privasi berbasis Zero-Knowledge Proof pada saluran MCP yang memverifikasi kepatuhan format dan keabsahan pesan tanpa mengungkap isi komunikasi. | M18: tidak | N18: gateway_proxy | O18: R4;R6 | P18: C3;D1 | Q18: C3;D1 | R18: author_run | T18: authors_own | U18: tidak | W18: Sec V; Table III; Table IV; hal. 8-11 | X18: none | Y18: latensi bukti ZK (< 50ms) dan overhead transmisi dilaporkan (Sec V) | Z18: Protokol audit privasi berbasis Zero-Knowledge Proof (zk-MCP) terintegrasi pada kanal MCP. Penegakan kriptografis deterministik (Circom ZK circuit). Dievaluasi pada testbed komunikasi multi-agen IoA. Catatan deployment: prototipe internal/eksperimental (belum dirilis secara publik). | AA18: =IF(I18="","",IF(OR(I18="attack",I18="survey_review",I18="benchmark_measurement",I18="position_other",I18="not_defense"),"n/a",IF(OR(X18="spec_normatif",X18="produksi_bukti_publik"),"L3",IF(ISNUMBER(SEARCH("independent",R18)),"L2",IF(R18="author_run","L1",IF(R18="none","L0","")))))) | AB18: =IF(I18="","",IF(AND(K18="deterministic_policy",M18="ya"),"PERIKSA: deterministic_policy tetapi LLM/ML ada dalam keputusan. ","")&IF(AND(U18="ya",V18=""),"PERIKSA: adaptif=ya wajib ada kutipan. ","")&IF(AND(R18="none",U18<>"n/a_tanpa_evaluasi",U18<>""),"PERIKSA: tanpa evaluasi, adaptif harus n/a. ","")&IF(AND(OR(R18="author_run",R18="author_run+independent",R18="independent_only"),Q18=""),"PERIKSA: isi kelas_dievaluasi. ","")&IF(AND(OR(R18="author_run",R18="author_run+independent",R18="independent_only"),W18=""),"PERIKSA: isi lokasi_bukti. ","")&IF(AND(H18="tidak",R18<>""),"PERIKSA: tanpa teks lengkap, kosongkan kolom evaluasi. ","")) | AC18: include
A19: haiyue-2026-agent-audit-security-analysis-system | B19: Agent Audit: A Security Analysis System for LLM Agent Applications | C19: 2026 | D19: E2 | E19: kandidat_agent | F19: primary | G19: https://arxiv.org/abs/2603.22853 | H19: tidak | I19: not_defense | Z19: [AUDIT_v5_EXCLUDE: EC2] Dikeluarkan dari korpus MCP-spesifik oleh audit reviewer kedua v5. Analisis keamanan aplikasi agen LLM umum dengan MCP hanya salah satu format tool insidental. | AA19: =IF(I19="","",IF(OR(I19="attack",I19="survey_review",I19="benchmark_measurement",I19="position_other",I19="not_defense"),"n/a",IF(OR(X19="spec_normatif",X19="produksi_bukti_publik"),"L3",IF(ISNUMBER(SEARCH("independent",R19)),"L2",IF(R19="author_run","L1",IF(R19="none","L0","")))))) | AB19: =IF(I19="","",IF(AND(K19="deterministic_policy",M19="ya"),"PERIKSA: deterministic_policy tetapi LLM/ML ada dalam keputusan. ","")&IF(AND(U19="ya",V19=""),"PERIKSA: adaptif=ya wajib ada kutipan. ","")&IF(AND(R19="none",U19<>"n/a_tanpa_evaluasi",U19<>""),"PERIKSA: tanpa evaluasi, adaptif harus n/a. ","")&IF(AND(OR(R19="author_run",R19="author_run+independent",R19="independent_only"),Q19=""),"PERIKSA: isi kelas_dievaluasi. ","")&IF(AND(OR(R19="author_run",R19="author_run+independent",R19="independent_only"),W19=""),"PERIKSA: isi lokasi_bukti. ","")&IF(AND(H19="tidak",R19<>""),"PERIKSA: tanpa teks lengkap, kosongkan kolom evaluasi. ","")) | AC19: exclude | AD19: EC2 | AE19: audit lanjutan; diterima koordinator
A20: huan-2026-zero-trust-authorization-discovery-enterprise | B20: Zero-Trust Authorization and Discovery for Enterprise MCP | C20: 2026 | D20: E2 | E20: kandidat_agent | F20: primary | G20: https://arxiv.org/abs/2609.22573 | H20: ya | I20: defense_primary | J20: FastMCP Zero-Trust Extensions | K20: deterministic_policy | L20: Ekstensi zero-trust middleware FastMCP yang menyediakan otorisasi per-tool AND/OR deklaratif, autentikasi dual-persona, serta cache introspeksi token untuk validasi kontinu. | M20: tidak | N20: gateway_proxy | O20: R3;R4;R5 | P20: C1;C2;C3;C5 | Q20: C1;C2;C3;C5 | R20: author_run | T20: authors_own | U20: tidak | W20: Sec 4.1; Sec 4.2; Sec 4.3; Table 2; Table 3; Table 4; hal. 6-10 | X20: none | Y20: latensi (p50: 9.9 ms vs 296 ms, Tabel 2) dan trace produksi 7 hari dilaporkan (Sec 4.2) | Z20: Ekstensi zero-trust untuk FastMCP oleh insinyur PayPal yang menambahkan otorisasi per-tool, dual-persona auth, dan cache introspeksi token. Diuji secara adversarial pada testbed alat Kubernetes dan dievaluasi pada jejak produksi PayPal 7 hari. Catatan deployment: prototipe internal/eksperimental (belum dirilis secara publik). | AA20: =IF(I20="","",IF(OR(I20="attack",I20="survey_review",I20="benchmark_measurement",I20="position_other",I20="not_defense"),"n/a",IF(OR(X20="spec_normatif",X20="produksi_bukti_publik"),"L3",IF(ISNUMBER(SEARCH("independent",R20)),"L2",IF(R20="author_run","L1",IF(R20="none","L0","")))))) | AB20: =IF(I20="","",IF(AND(K20="deterministic_policy",M20="ya"),"PERIKSA: deterministic_policy tetapi LLM/ML ada dalam keputusan. ","")&IF(AND(U20="ya",V20=""),"PERIKSA: adaptif=ya wajib ada kutipan. ","")&IF(AND(R20="none",U20<>"n/a_tanpa_evaluasi",U20<>""),"PERIKSA: tanpa evaluasi, adaptif harus n/a. ","")&IF(AND(OR(R20="author_run",R20="author_run+independent",R20="independent_only"),Q20=""),"PERIKSA: isi kelas_dievaluasi. ","")&IF(AND(OR(R20="author_run",R20="author_run+independent",R20="independent_only"),W20=""),"PERIKSA: isi lokasi_bukti. ","")&IF(AND(H20="tidak",R20<>""),"PERIKSA: tanpa teks lengkap, kosongkan kolom evaluasi. ","")) | AC20: include
A21: huihao-2025-mcip-protecting-mcp-safety-via | B21: MCIP: Protecting MCP Safety via Model Contextual Integrity Protocol | C21: 2025 | D21: E1 | E21: kandidat_agent | F21: primary | G21: https://doi.org/10.18653/v1/2025.emnlp-main.62 | H21: ya | I21: defense_primary | J21: MCIP | K21: content_inspection_runtime | L21: Protokol integritas kontekstual dengan model pelindung (MCIP Guardian) yang mengawasi alur konteks interaksi MCP dan mendeteksi aksi tidak aman pada pemanggilan tool. | M21: ya | N21: H | O21: R2;R5;R6 | P21: A1;A2;C5;D1 | Q21: A1;A2;C5;D1 | R21: author_run+independent | S21: yixuan-2025-mcpsecbench-systematic-security-benchmark-playground | T21: mixed | U21: tidak | W21: Sec 6; Sec 7; Table 2; Fig 5; hal. 6-9 | X21: none | Y21: trade-off utilitas BFCL dan resistensi risiko dilaporkan (Tabel 2, Fig 5) | Z21: Kerangka pengamanan MCP berbasis protokol integritas kontekstual (MCIP) dan model pelindung (MCIP Guardian). Dievaluasi secara independen oleh MCPSecBench (yixuan-2025) pada 3 platform MCP (Tabel 1, 2, Fig 4, 6) sehingga mencapai maturitas L2. Catatan deployment: prototipe internal/eksperimental (belum dirilis secara publik). | AA21: =IF(I21="","",IF(OR(I21="attack",I21="survey_review",I21="benchmark_measurement",I21="position_other",I21="not_defense"),"n/a",IF(OR(X21="spec_normatif",X21="produksi_bukti_publik"),"L3",IF(ISNUMBER(SEARCH("independent",R21)),"L2",IF(R21="author_run","L1",IF(R21="none","L0","")))))) | AB21: =IF(I21="","",IF(AND(K21="deterministic_policy",M21="ya"),"PERIKSA: deterministic_policy tetapi LLM/ML ada dalam keputusan. ","")&IF(AND(U21="ya",V21=""),"PERIKSA: adaptif=ya wajib ada kutipan. ","")&IF(AND(R21="none",U21<>"n/a_tanpa_evaluasi",U21<>""),"PERIKSA: tanpa evaluasi, adaptif harus n/a. ","")&IF(AND(OR(R21="author_run",R21="author_run+independent",R21="independent_only"),Q21=""),"PERIKSA: isi kelas_dievaluasi. ","")&IF(AND(OR(R21="author_run",R21="author_run+independent",R21="independent_only"),W21=""),"PERIKSA: isi lokasi_bukti. ","")&IF(AND(H21="tidak",R21<>""),"PERIKSA: tanpa teks lengkap, kosongkan kolom evaluasi. ","")) | AC21: include
A22: ignacio-2026-crud-autonomous-agents-formal-validation | B22: From CRUD to Autonomous Agents: Formal Validation and Zero-Trust Security for Semantic Gateways in AI-Native Enterprise Systems | C22: 2026 | D22: E2 | E22: kandidat_agent | F22: primary | G22: https://arxiv.org/abs/2604.25555 | H22: ya | I22: defense_primary | J22: Semantic Gateway | K22: deterministic_policy | L22: Gateway semantik zero-trust dengan validasi formal transisi state (EPA) dan penegakan kebijakan OPA/Rego deterministik untuk mencegah pelanggaran otorisasi BOLA. | M22: tidak | N22: gateway_proxy | O22: R3;R5 | P22: C1;C2;C5 | Q22: C1;C2;C5 | R22: author_run | T22: authors_own | U22: tidak | W22: Sec 8; Sec 8.3; Sec 8.4; Table 2; Table 3; hal. 14-16 | X22: prototype_open_source | Y22: latensi gateway semantik vs traditional REST baseline dilaporkan (Tabel 3) | Z22: Gateway semantik zero-trust dengan penegakan kebijakan deterministik OPA/Rego dan validasi formal graf EPA. Dievaluasi dengan semantic fuzzer 500 iterasi dan 47 kasus uji, menolak pelanggaran BOLA dan transisi ilegal. Repositori/artefak: https://github.com/PeyranoDev/semantic-gateway-poc. | AA22: =IF(I22="","",IF(OR(I22="attack",I22="survey_review",I22="benchmark_measurement",I22="position_other",I22="not_defense"),"n/a",IF(OR(X22="spec_normatif",X22="produksi_bukti_publik"),"L3",IF(ISNUMBER(SEARCH("independent",R22)),"L2",IF(R22="author_run","L1",IF(R22="none","L0","")))))) | AB22: =IF(I22="","",IF(AND(K22="deterministic_policy",M22="ya"),"PERIKSA: deterministic_policy tetapi LLM/ML ada dalam keputusan. ","")&IF(AND(U22="ya",V22=""),"PERIKSA: adaptif=ya wajib ada kutipan. ","")&IF(AND(R22="none",U22<>"n/a_tanpa_evaluasi",U22<>""),"PERIKSA: tanpa evaluasi, adaptif harus n/a. ","")&IF(AND(OR(R22="author_run",R22="author_run+independent",R22="independent_only"),Q22=""),"PERIKSA: isi kelas_dievaluasi. ","")&IF(AND(OR(R22="author_run",R22="author_run+independent",R22="independent_only"),W22=""),"PERIKSA: isi lokasi_bukti. ","")&IF(AND(H22="tidak",R22<>""),"PERIKSA: tanpa teks lengkap, kosongkan kolom evaluasi. ","")) | AC22: include
A23: ivo-2025-simplified-secure-mcp-gateways-enterprise | B23: Simplified and Secure MCP Gateways for Enterprise AI Integration | C23: 2025 | D23: E2 | E23: kandidat_agent | F23: primary | G23: https://doi.org/10.48550/arxiv.2504.19997 | H23: ya | I23: defense_primary | J23: MCP Gateway | K23: deterministic_policy | L23: Arsitektur gateway pengaman MCP enterprise self-hosted berbasis OAuth2-proxy, reverse proxy Traefik, CrowdSec IDS/WAF, dan tunnel WireGuard. | M23: tidak | N23: gateway_proxy | O23: R4;R5 | P23: C3;C5 | Q23: C3;C5 | R23: author_run | T23: authors_own | U23: tidak | W23: Sec VIII; Table I; Table II; hal. 4-6 | X23: none | Y23: not_reported | Z23: Arsitektur gateway pengaman MCP enterprise self-hosted berbasis OAuth2-proxy, Traefik, CrowdSec, dan tunnel WireGuard. Penegakan deterministik pada gateway proxy menolak permintaan tanpa autentikasi dan token tidak sah. Catatan deployment: prototipe internal/eksperimental (belum dirilis secara publik). | AA23: =IF(I23="","",IF(OR(I23="attack",I23="survey_review",I23="benchmark_measurement",I23="position_other",I23="not_defense"),"n/a",IF(OR(X23="spec_normatif",X23="produksi_bukti_publik"),"L3",IF(ISNUMBER(SEARCH("independent",R23)),"L2",IF(R23="author_run","L1",IF(R23="none","L0","")))))) | AB23: =IF(I23="","",IF(AND(K23="deterministic_policy",M23="ya"),"PERIKSA: deterministic_policy tetapi LLM/ML ada dalam keputusan. ","")&IF(AND(U23="ya",V23=""),"PERIKSA: adaptif=ya wajib ada kutipan. ","")&IF(AND(R23="none",U23<>"n/a_tanpa_evaluasi",U23<>""),"PERIKSA: tanpa evaluasi, adaptif harus n/a. ","")&IF(AND(OR(R23="author_run",R23="author_run+independent",R23="independent_only"),Q23=""),"PERIKSA: isi kelas_dievaluasi. ","")&IF(AND(OR(R23="author_run",R23="author_run+independent",R23="independent_only"),W23=""),"PERIKSA: isi lokasi_bukti. ","")&IF(AND(H23="tidak",R23<>""),"PERIKSA: tanpa teks lengkap, kosongkan kolom evaluasi. ","")) | AC23: include
A24: jalendar-2025-zero-trust-proof-gated-agent | B24: Zero-Trust Proof-Gated Agent Architecture (ZPAA): A Comprehensive Security Model for the Model Context Protocol (MCP) | C24: 2025 | D24: E2 | E24: kandidat_agent | F24: primary | G24: https://doi.org/10.22541/au.175761889.90929465/v1 | H24: tidak | I24: defense_primary | J24: Zero-Trust Proof-Gated Agent Architecture | K24: deterministic_policy | L24: Model arsitektur agen zero-trust berbasis bukti untuk memvalidasi interaksi dan izin pemanggilan Model Context Protocol. | M24: tidak | N24: gateway_proxy | O24: R3;R4 | P24: C3;C1 | Z24: [NON-OA / ABSTRACT-ONLY] Artikel Authorea dengan akses terbatas. Arsitektur agen proof-gated zero-trust untuk memverifikasi bukti kriptografis sebelum eksekusi aksi (C3, C1). | AA24: =IF(I24="","",IF(OR(I24="attack",I24="survey_review",I24="benchmark_measurement",I24="position_other",I24="not_defense"),"n/a",IF(OR(X24="spec_normatif",X24="produksi_bukti_publik"),"L3",IF(ISNUMBER(SEARCH("independent",R24)),"L2",IF(R24="author_run","L1",IF(R24="none","L0","")))))) | AB24: =IF(I24="","",IF(AND(K24="deterministic_policy",M24="ya"),"PERIKSA: deterministic_policy tetapi LLM/ML ada dalam keputusan. ","")&IF(AND(U24="ya",V24=""),"PERIKSA: adaptif=ya wajib ada kutipan. ","")&IF(AND(R24="none",U24<>"n/a_tanpa_evaluasi",U24<>""),"PERIKSA: tanpa evaluasi, adaptif harus n/a. ","")&IF(AND(OR(R24="author_run",R24="author_run+independent",R24="independent_only"),Q24=""),"PERIKSA: isi kelas_dievaluasi. ","")&IF(AND(OR(R24="author_run",R24="author_run+independent",R24="independent_only"),W24=""),"PERIKSA: isi lokasi_bukti. ","")&IF(AND(H24="tidak",R24<>""),"PERIKSA: tanpa teks lengkap, kosongkan kolom evaluasi. ","")) | AC24: include
A25: lichao-2026-safemcp-proactive-power-regulation-llm | B25: SafeMCP: Proactive Power Regulation for LLM Agent Defense via Environment-Grounded Look-Ahead Reasoning | C25: 2026 | D25: E2 | E25: kandidat_agent | F25: primary | G25: https://arxiv.org/abs/2606.01991 | H25: tidak | I25: not_defense | Z25: [AUDIT_v5_EXCLUDE: EC2] Dikeluarkan dari korpus MCP-spesifik oleh audit reviewer kedua v5. Regulasi proaktif agen LLM umum via look-ahead reasoning di mana MCP insidental. | AA25: =IF(I25="","",IF(OR(I25="attack",I25="survey_review",I25="benchmark_measurement",I25="position_other",I25="not_defense"),"n/a",IF(OR(X25="spec_normatif",X25="produksi_bukti_publik"),"L3",IF(ISNUMBER(SEARCH("independent",R25)),"L2",IF(R25="author_run","L1",IF(R25="none","L0","")))))) | AB25: =IF(I25="","",IF(AND(K25="deterministic_policy",M25="ya"),"PERIKSA: deterministic_policy tetapi LLM/ML ada dalam keputusan. ","")&IF(AND(U25="ya",V25=""),"PERIKSA: adaptif=ya wajib ada kutipan. ","")&IF(AND(R25="none",U25<>"n/a_tanpa_evaluasi",U25<>""),"PERIKSA: tanpa evaluasi, adaptif harus n/a. ","")&IF(AND(OR(R25="author_run",R25="author_run+independent",R25="independent_only"),Q25=""),"PERIKSA: isi kelas_dievaluasi. ","")&IF(AND(OR(R25="author_run",R25="author_run+independent",R25="independent_only"),W25=""),"PERIKSA: isi lokasi_bukti. ","")&IF(AND(H25="tidak",R25<>""),"PERIKSA: tanpa teks lengkap, kosongkan kolom evaluasi. ","")) | AC25: exclude | AD25: EC2 | AE25: audit lanjutan; diterima koordinator
A26: manish-2025-etdi-mitigating-tool-squatting-rug | B26: ETDI: Mitigating Tool Squatting and Rug Pull Attacks in Model Context Protocol (MCP) by using OAuth-Enhanced Tool Definitions and Policy-Based Access Control | C26: 2025 | D26: E1 | E26: kandidat_agent | F26: primary | G26: https://arxiv.org/abs/2506.01333 | H26: ya | I26: defense_primary | J26: ETDI | K26: cryptographic_integrity | L26: Spesifikasi antarmuka Enhanced Tool Definition Interface (ETDI) dengan verifikasi identitas kriptografis, versi definisi immutable, dan kebijakan Cedar/OPA untuk mitigasi tool squatting dan rug pull. | M26: tidak | N26: G | O26: R1;R6 | P26: A1;B1 | R26: none | T26: none | U26: n/a_tanpa_evaluasi | W26: Sec. 3-4, hal. 4-6 | X26: none | Y26: not_reported | Z26: Spesifikasi Enhanced Tool Definition Interface (ETDI) dengan verifikasi identitas kriptografis, versi immutable, dan integrasi kebijakan Cedar/OPA untuk mitigasi tool squatting dan rug pull. Tanpa evaluasi empiris (L0). | AA26: =IF(I26="","",IF(OR(I26="attack",I26="survey_review",I26="benchmark_measurement",I26="position_other",I26="not_defense"),"n/a",IF(OR(X26="spec_normatif",X26="produksi_bukti_publik"),"L3",IF(ISNUMBER(SEARCH("independent",R26)),"L2",IF(R26="author_run","L1",IF(R26="none","L0","")))))) | AB26: =IF(I26="","",IF(AND(K26="deterministic_policy",M26="ya"),"PERIKSA: deterministic_policy tetapi LLM/ML ada dalam keputusan. ","")&IF(AND(U26="ya",V26=""),"PERIKSA: adaptif=ya wajib ada kutipan. ","")&IF(AND(R26="none",U26<>"n/a_tanpa_evaluasi",U26<>""),"PERIKSA: tanpa evaluasi, adaptif harus n/a. ","")&IF(AND(OR(R26="author_run",R26="author_run+independent",R26="independent_only"),Q26=""),"PERIKSA: isi kelas_dievaluasi. ","")&IF(AND(OR(R26="author_run",R26="author_run+independent",R26="independent_only"),W26=""),"PERIKSA: isi lokasi_bukti. ","")&IF(AND(H26="tidak",R26<>""),"PERIKSA: tanpa teks lengkap, kosongkan kolom evaluasi. ","")) | AC26: include
A27: mirza-2026-stochastic-deputy-structural-tenant-isolation | B27: The Stochastic Deputy: Structural Tenant Isolation for Tool-Using LLM Agents | C27: 2026 | D27: E2 | E27: kandidat_agent | F27: primary | G27: https://arxiv.org/abs/2609.14780 | H27: ya | I27: defense_primary | J27: Structural Tenant Isolation | K27: deterministic_policy | L27: Pertahanan struktural terhadap masalah stochastic deputy dengan menghapus parameter tenant dari skema tool MCP dan menegakkan isolasi tenant di bawah agen melalui credential binding dan query rewriting. | M27: tidak | N27: S | O27: R3;R5 | P27: C1;C2;D1 | Q27: C1;C2;D1 | R27: author_run | T27: authors_own | U27: tidak | W27: Sec 8; Sec 8.1; Table 1; Table 2; hal. 8-15 | X27: none | Y27: latensi dan rasio optimasi query MySQL dilaporkan (Sec 8, RQ2) | Z27: Pertahanan isolasi multi-tenant struktural (structural tenant isolation) terhadap masalah stochastic deputy dengan menghapus parameter tenant dari skema tool MCP dan mengikat lingkup pada kredensial terverifikasi. Dievaluasi pada 373 uji lintas 8 LLM dan basis data MySQL multi-GB. Catatan deployment: prototipe internal/eksperimental (belum dirilis secara publik). | AA27: =IF(I27="","",IF(OR(I27="attack",I27="survey_review",I27="benchmark_measurement",I27="position_other",I27="not_defense"),"n/a",IF(OR(X27="spec_normatif",X27="produksi_bukti_publik"),"L3",IF(ISNUMBER(SEARCH("independent",R27)),"L2",IF(R27="author_run","L1",IF(R27="none","L0","")))))) | AB27: =IF(I27="","",IF(AND(K27="deterministic_policy",M27="ya"),"PERIKSA: deterministic_policy tetapi LLM/ML ada dalam keputusan. ","")&IF(AND(U27="ya",V27=""),"PERIKSA: adaptif=ya wajib ada kutipan. ","")&IF(AND(R27="none",U27<>"n/a_tanpa_evaluasi",U27<>""),"PERIKSA: tanpa evaluasi, adaptif harus n/a. ","")&IF(AND(OR(R27="author_run",R27="author_run+independent",R27="independent_only"),Q27=""),"PERIKSA: isi kelas_dievaluasi. ","")&IF(AND(OR(R27="author_run",R27="author_run+independent",R27="independent_only"),W27=""),"PERIKSA: isi lokasi_bukti. ","")&IF(AND(H27="tidak",R27<>""),"PERIKSA: tanpa teks lengkap, kosongkan kolom evaluasi. ","")) | AC27: include
A28: nirajan-2026-formal-security-framework-mcp-based | B28: A Formal Security Framework for MCP-Based AI Agents: Threat Taxonomy, Verification Models, and Defense Mechanisms | C28: 2026 | D28: E2 | E28: kandidat_agent | F28: primary | G28: https://arxiv.org/abs/2604.05969 | H28: ya | I28: proposal_only | J28: MCPSHIELD | K28: protocol_provision | L28: Kerangka formal dan arsitektur defense-in-depth empat lapis (MCPSHIELD) berbasis model verifikasi formal Labeled Transition Systems untuk mengamankan ekosistem agen MCP. | M28: tidak | N28: gateway_proxy | O28: R1;R2;R3;R4;R5;R6;R7 | P28: A1;A2;B1;B2;C1;C3;C5;D1;D3 | R28: none | T28: none | U28: n/a_tanpa_evaluasi | X28: none | Y28: not_reported | Z28: Kerangka keamanan formal dan arsitektur defense-in-depth berlapis (MCPSHIELD) berbasis model verifikasi formal Labeled Transition Systems (LTS). Tidak menyertakan evaluasi empiris pertahanan terhadap serangan. KODER 1 menandai defense_primary dengan jenis_evaluasi none (L0). | AA28: =IF(I28="","",IF(OR(I28="attack",I28="survey_review",I28="benchmark_measurement",I28="position_other",I28="not_defense"),"n/a",IF(OR(X28="spec_normatif",X28="produksi_bukti_publik"),"L3",IF(ISNUMBER(SEARCH("independent",R28)),"L2",IF(R28="author_run","L1",IF(R28="none","L0","")))))) | AB28: =IF(I28="","",IF(AND(K28="deterministic_policy",M28="ya"),"PERIKSA: deterministic_policy tetapi LLM/ML ada dalam keputusan. ","")&IF(AND(U28="ya",V28=""),"PERIKSA: adaptif=ya wajib ada kutipan. ","")&IF(AND(R28="none",U28<>"n/a_tanpa_evaluasi",U28<>""),"PERIKSA: tanpa evaluasi, adaptif harus n/a. ","")&IF(AND(OR(R28="author_run",R28="author_run+independent",R28="independent_only"),Q28=""),"PERIKSA: isi kelas_dievaluasi. ","")&IF(AND(OR(R28="author_run",R28="author_run+independent",R28="independent_only"),W28=""),"PERIKSA: isi lokasi_bukti. ","")&IF(AND(H28="tidak",R28<>""),"PERIKSA: tanpa teks lengkap, kosongkan kolom evaluasi. ","")) | AC28: include
A29: parya-2026-mcp-scanner-detecting-security-risks | B29: MCP-Scanner: Detecting Security Risks in Model Context Protocol Systems | C29: 2026 | D29: E1 | E29: kandidat_agent | F29: primary | G29: https://doi.org/10.1145/3786160.3788471 | H29: ya | I29: defense_primary | J29: MCP-Scanner (eSentire MCP-Scanner) | K29: content_inspection_static | L29: Pemindai komprehensif multi-layer (kata kunci, SentenceTransformer embeddings, dan LLM-as-judge) untuk memeriksa keamanan tools, prompts, dan resources server MCP. | M29: ya | N29: offline_analysis | O29: R1;R2;R3;R5;R7 | P29: A1;A2;B2;C1;D3 | Q29: A1;A2;D3 | R29: author_run | T29: mixed | U29: tidak | W29: Sec. 6, Tabel 1 & 2, hal. 6-8 | X29: none | Y29: cakupan deteksi 13 kategori kerentanan pada 14 server MCP (Tabel 1 & 2) | Z29: MCP-Scanner (defense_primary, L1). Evaluasi pemindaian statis AST/regex pada 14 server MCP (Tabel 2). Tabel 1 membandingkan 22 kategori kerentanan komparatif secara literatur (14 kategori diklaim terdeteksi oleh MCP-Scanner); tidak ada eksekusi eksperimen kuantitatif terhadap perkakas lain sehingga ditolak sebagai evaluator L2. | AA29: =IF(I29="","",IF(OR(I29="attack",I29="survey_review",I29="benchmark_measurement",I29="position_other",I29="not_defense"),"n/a",IF(OR(X29="spec_normatif",X29="produksi_bukti_publik"),"L3",IF(ISNUMBER(SEARCH("independent",R29)),"L2",IF(R29="author_run","L1",IF(R29="none","L0","")))))) | AB29: =IF(I29="","",IF(AND(K29="deterministic_policy",M29="ya"),"PERIKSA: deterministic_policy tetapi LLM/ML ada dalam keputusan. ","")&IF(AND(U29="ya",V29=""),"PERIKSA: adaptif=ya wajib ada kutipan. ","")&IF(AND(R29="none",U29<>"n/a_tanpa_evaluasi",U29<>""),"PERIKSA: tanpa evaluasi, adaptif harus n/a. ","")&IF(AND(OR(R29="author_run",R29="author_run+independent",R29="independent_only"),Q29=""),"PERIKSA: isi kelas_dievaluasi. ","")&IF(AND(OR(R29="author_run",R29="author_run+independent",R29="independent_only"),W29=""),"PERIKSA: isi lokasi_bukti. ","")&IF(AND(H29="tidak",R29<>""),"PERIKSA: tanpa teks lengkap, kosongkan kolom evaluasi. ","")) | AC29: include
A30: pek-2026-cascade-component-ablation-corpus-audit | B30: CASCADE: A Component Ablation and Corpus Audit of a Layered Local Defense for MCP-Based Systems | C30: 2026 | D30: E2 | E30: kandidat_agent | F30: primary | G30: https://arxiv.org/abs/2604.17125 | H30: ya | I30: defense_primary | J30: CASCADE | K30: content_inspection_runtime | L30: Pertahanan berlapis lokal untuk sistem MCP yang memadukan filter kemiripan embedding cepat dan model review lokal Llama-3 8B untuk menangani permintaan ambigu/mencurigakan. | M30: ya | N30: H | O30: R2 | P30: A1;A2 | Q30: A1;A2 | R30: author_run | T30: mixed | U30: tidak | W30: Sec 4; Sec 4.1; Sec 4.2; Table 5; Table 6; hal. 8-15 | X30: none | Y30: latensi per tahap, throughput, dan tingkat pemanggilan model review (32.56%) dilaporkan (Sec 4) | Z30: Pertahanan berlapis lokal untuk sistem MCP (CASCADE) memadukan embedding filter deterministik dan model review lokal Llama-3 8B. Dievaluasi secara ketat pada 5.000 sampel korpus riil/augmentasi dengan ablasi komponen menyeluruh. Catatan deployment: prototipe internal/eksperimental (belum dirilis secara publik). | AA30: =IF(I30="","",IF(OR(I30="attack",I30="survey_review",I30="benchmark_measurement",I30="position_other",I30="not_defense"),"n/a",IF(OR(X30="spec_normatif",X30="produksi_bukti_publik"),"L3",IF(ISNUMBER(SEARCH("independent",R30)),"L2",IF(R30="author_run","L1",IF(R30="none","L0","")))))) | AB30: =IF(I30="","",IF(AND(K30="deterministic_policy",M30="ya"),"PERIKSA: deterministic_policy tetapi LLM/ML ada dalam keputusan. ","")&IF(AND(U30="ya",V30=""),"PERIKSA: adaptif=ya wajib ada kutipan. ","")&IF(AND(R30="none",U30<>"n/a_tanpa_evaluasi",U30<>""),"PERIKSA: tanpa evaluasi, adaptif harus n/a. ","")&IF(AND(OR(R30="author_run",R30="author_run+independent",R30="independent_only"),Q30=""),"PERIKSA: isi kelas_dievaluasi. ","")&IF(AND(OR(R30="author_run",R30="author_run+independent",R30="independent_only"),W30=""),"PERIKSA: isi lokasi_bukti. ","")&IF(AND(H30="tidak",R30<>""),"PERIKSA: tanpa teks lengkap, kosongkan kolom evaluasi. ","")) | AC30: include
A31: ping-2026-hybrid-analysis-secure-mcp-tool | B31: Hybrid Analysis for Secure MCP Tool Use in LLM Agents | C31: 2026 | D31: E2 | E31: kandidat_agent | F31: primary | G31: https://arxiv.org/abs/2607.25297 | H31: ya | I31: defense_primary | J31: MTGuard | K31: content_inspection_runtime | L31: Kerangka analisis hibrida siklus hidup (MTGuard) yang mengombinasikan asesmen risiko pra-eksekusi dan verifikasi hasil pasca-eksekusi pada pemanggilan tool MCP. | M31: ya | N31: H | O31: R2;R5 | P31: A1;A2;C5 | Q31: A1;A2;C5 | R31: author_run | T31: mixed | U31: tidak | W31: Sec 5; Table 1; Table 2; Table 3; hal. 6-10 | X31: none | Y31: latensi runtime dan false positive rate dilaporkan (Sec 5, Tabel 2) | Z31: Framework pertahanan analisis hibrida (MTGuard) yang mengombinasikan asesmen pra-eksekusi dan verifikasi pasca-eksekusi pemanggilan tool MCP. Dievaluasi pada agen otomatisasi peramban dan analisis finansial, mencapai rata-rata detection rate 48.3% vs baseline 8.3%. Catatan deployment: prototipe internal/eksperimental (belum dirilis secara publik). | AA31: =IF(I31="","",IF(OR(I31="attack",I31="survey_review",I31="benchmark_measurement",I31="position_other",I31="not_defense"),"n/a",IF(OR(X31="spec_normatif",X31="produksi_bukti_publik"),"L3",IF(ISNUMBER(SEARCH("independent",R31)),"L2",IF(R31="author_run","L1",IF(R31="none","L0","")))))) | AB31: =IF(I31="","",IF(AND(K31="deterministic_policy",M31="ya"),"PERIKSA: deterministic_policy tetapi LLM/ML ada dalam keputusan. ","")&IF(AND(U31="ya",V31=""),"PERIKSA: adaptif=ya wajib ada kutipan. ","")&IF(AND(R31="none",U31<>"n/a_tanpa_evaluasi",U31<>""),"PERIKSA: tanpa evaluasi, adaptif harus n/a. ","")&IF(AND(OR(R31="author_run",R31="author_run+independent",R31="independent_only"),Q31=""),"PERIKSA: isi kelas_dievaluasi. ","")&IF(AND(OR(R31="author_run",R31="author_run+independent",R31="independent_only"),W31=""),"PERIKSA: isi lokasi_bukti. ","")&IF(AND(H31="tidak",R31<>""),"PERIKSA: tanpa teks lengkap, kosongkan kolom evaluasi. ","")) | AC31: include
